<?xml version="1.0" ?>
<!-- =================================================================================== -->
<!-- |    This document was autogenerated by xacro from m1n6s300_standalone.xacro      | -->
<!-- |    EDITING THIS FILE BY HAND IS NOT RECOMMENDED                                 | -->
<!-- =================================================================================== -->
<!-- m1n6_2 refers to mico v1 6DOF non-spherical 2fingers -->
<robot name="m1n6s300" xmlns:body="http://playerstage.sourceforge.net/gazebo/xmlschema/#body" xmlns:controller="http://playerstage.sourceforge.net/gazebo/xmlschema/#controller" xmlns:gazebo="http://playerstage.sourceforge.net/gazebo/xmlschema/#gz" xmlns:geom="http://playerstage.sourceforge.net/gazebo/xmlschema/#geom" xmlns:interface="http://playerstage.sourceforge.net/gazebo/xmlschema/#interface" xmlns:joint="http://playerstage.sourceforge.net/gazebo/xmlschema/#joint" xmlns:model="http://playerstage.sourceforge.net/gazebo/xmlschema/#model" xmlns:physics="http://playerstage.sourceforge.net/gazebo/xmlschema/#physics" xmlns:renderable="http://playerstage.sourceforge.net/gazebo/xmlschema/#renderable" xmlns:rendering="http://playerstage.sourceforge.net/gazebo/xmlschema/#rendering" xmlns:sensor="http://playerstage.sourceforge.net/gazebo/xmlschema/#sensor" xmlns:xacro="http://ros.org/wiki/xacro" xmlns:xi="http://www.w3.org/2001/XInclude">
  <!-- links      		mesh_no
   base           		0
   shoulder       		1
   arm            		2
   forearm        		3
   wrist          		4
   arm_mico       		5
   arm_half1 (7dof)		6
   arm_half2 (7dof)		7
   wrist_spherical_1  8
   wrist_spherical_2  9

   hand 3 finger  		55
   hand_2finger   		56
   finger_proximal		57
   finger_distal      58 
-->
  <!-- links      		mesh_no
   base           		0
   shoulder       		1
   arm            		2
   forearm        		3
   wrist          		4
   arm_mico       		5
   arm_half1 (7dof)		6
   arm_half2 (7dof)		7
   wrist_spherical_1  8
   wrist_spherical_2  9

   hand 3 finger  		55
   hand_2finger   		56
   finger_proximal		57
   finger_distal      58 
-->
  <link name="root">
    <visual>
      <origin rpy="0 0 0" xyz="0 0 0"/>
      <geometry>
        <box size="0.01 0.01 0.01"/>
      </geometry>
      <!--<material name="Black" /> -->
    </visual>
    <collision>
      <origin rpy="0 0 0" xyz="0 0 0"/>
      <geometry>
        <box size="0.01 0.01 0.01"/>
      </geometry>
    </collision>
  </link>
  <!-- for gazebo -->
  <link name="world"/>
  <joint name="connect_root_and_world" type="fixed">
    <child link="root"/>
    <parent link="world"/>
    <origin rpy="0 0 0" xyz="0 0 0"/>
  </joint>
  <!-- ros_control plugin -->
  <gazebo>
    <plugin filename="libgazebo_ros_control.so" name="gazebo_ros_control">
      <robotNamespace>m1n6s300</robotNamespace>
      <robotSimType>gazebo_ros_control/DefaultRobotHWSim</robotSimType>
    </plugin>
  </gazebo>
  <link name="m1n6s300_link_base">
    <visual>
      <geometry>
        <mesh filename="meshes/base.dae"/>
      </geometry>
      <material name="carbon_fiber">
        <color rgba="0.792156862745098 0.819607843137255 0.933333333333333 1"/>
      </material>
    </visual>
    <collision>
      <geometry>
        <mesh filename="meshes/base.dae"/>
      </geometry>
    </collision>
    <inertial>
      <mass value="0.46784"/>
      <origin rpy="0 0 0" xyz="0 0 0.1255"/>
      <inertia ixx="0.000951270861568" ixy="0" ixz="0" iyy="0.000951270861568" iyz="0" izz="0.000374272"/>
    </inertial>
  </link>
  <joint name="m1n6s300_joint_base" type="fixed">
    <parent link="root"/>
    <child link="m1n6s300_link_base"/>
    <axis xyz="0 0 0"/>
    <limit effort="2000" lower="0" upper="0" velocity="1"/>
    <origin rpy="0 0 0" xyz="0 0 0"/>
    <dynamics damping="0.0" friction="0.0"/>
  </joint>
  <link name="m1n6s300_link_1">
    <visual>
      <geometry>
        <mesh filename="meshes/shoulder.dae"/>
      </geometry>
      <material name="carbon_fiber">
        <color rgba="0.792156862745098 0.819607843137255 0.933333333333333 1"/>
      </material>
    </visual>
    <visual>
      <geometry>
        <mesh filename="meshes/ring_big.STL"/>
      </geometry>
    </visual>
    <collision>
      <geometry>
        <mesh filename="meshes/shoulder.dae"/>
      </geometry>
    </collision>
    <inertial>
      <mass value="0.7477"/>
      <origin xyz="0 -0.002 -0.0605"/>
      <inertia ixx="0.00152031725204" ixy="0" ixz="0" iyy="0.00152031725204" iyz="0" izz="0.00059816"/>
    </inertial>
  </link>
  <joint name="m1n6s300_joint_1" type="continuous">
    <parent link="m1n6s300_link_base"/>
    <child link="m1n6s300_link_1"/>
    <axis xyz="0 0 1"/>
    <limit effort="2000" lower="-6.28318530718" upper="6.28318530718" velocity="1"/>
    <origin rpy="0 3.14159265359 0" xyz="0 0 0.15675"/>
    <dynamics damping="0.0" friction="0.0"/>
  </joint>
  <transmission name="m1n6s300_joint_1_trans">
    <type>transmission_interface/SimpleTransmission</type>
    <joint name="m1n6s300_joint_1">
      <hardwareInterface>EffortJointInterface</hardwareInterface>
    </joint>
    <actuator name="m1n6s300_joint_1_actuator">
      <hardwareInterface>EffortJointInterface</hardwareInterface>
      <mechanicalReduction>160</mechanicalReduction>
    </actuator>
  </transmission>
  <link name="m1n6s300_link_2">
    <visual>
      <geometry>
        <mesh filename="meshes/arm_mico.dae"/>
      </geometry>
      <material name="carbon_fiber">
        <color rgba="0.792156862745098 0.819607843137255 0.933333333333333 1"/>
      </material>
    </visual>
    <visual>
      <geometry>
        <mesh filename="meshes/ring_big.STL"/>
      </geometry>
    </visual>
    <collision>
      <geometry>
        <mesh filename="meshes/arm_mico.dae"/>
      </geometry>
    </collision>
    <inertial>
      <mass value="0.85968"/>
      <origin xyz="0 -0.145  -0.0076"/>
      <inertia ixx="0.00467090931629" ixy="0" ixz="0" iyy="0.000386856" iyz="0" izz="0.00467090931629"/>
    </inertial>
  </link>
  <joint name="m1n6s300_joint_2" type="revolute">
    <parent link="m1n6s300_link_1"/>
    <child link="m1n6s300_link_2"/>
    <axis xyz="0 0 1"/>
    <limit effort="2000" lower="-2.35" upper="2.35" velocity="1"/>
    <origin rpy="-1.5707963268 3.14159265359 3.1415926535897931" xyz="0 0.0016 -0.11875"/>
    <dynamics damping="0.0" friction="0.0"/>
  </joint>
  <transmission name="m1n6s300_joint_2_trans">
    <type>transmission_interface/SimpleTransmission</type>
    <joint name="m1n6s300_joint_2">
      <hardwareInterface>EffortJointInterface</hardwareInterface>
    </joint>
    <actuator name="m1n6s300_joint_2_actuator">
      <hardwareInterface>EffortJointInterface</hardwareInterface>
      <mechanicalReduction>160</mechanicalReduction>
    </actuator>
  </transmission>
  <link name="m1n6s300_link_3">
    <visual>
      <geometry>
        <mesh filename="meshes/forearm_mico.dae"/>
      </geometry>
      <material name="carbon_fiber">
        <color rgba="0.792156862745098 0.819607843137255 0.933333333333333 1"/>
      </material>
    </visual>
    <visual>
      <geometry>
        <mesh filename="meshes/ring_big.STL"/>
      </geometry>
    </visual>
    <collision>
      <geometry>
        <mesh filename="meshes/forearm_mico.dae"/>
      </geometry>
    </collision>
    <inertial>
      <mass value="0.606"/>
      <origin xyz="0 0.0463 -0.0065"/>
      <inertia ixx="0.0003837984648" ixy="0" ixz="0" iyy="0.0001212" iyz="0" izz="0.0003837984648"/>
    </inertial>
  </link>
  <joint name="m1n6s300_joint_3" type="revolute">
    <parent link="m1n6s300_link_2"/>
    <child link="m1n6s300_link_3"/>
    <axis xyz="0 0 1"/>
    <limit effort="2000" lower="-2.86" upper="2.86" velocity="1"/>
    <origin rpy="0 3.1415926535897931 3.14159265359" xyz="0 -0.290 0"/>
    <dynamics damping="0.0" friction="0.0"/>
  </joint>
  <transmission name="m1n6s300_joint_3_trans">
    <type>transmission_interface/SimpleTransmission</type>
    <joint name="m1n6s300_joint_3">
      <hardwareInterface>EffortJointInterface</hardwareInterface>
    </joint>
    <actuator name="m1n6s300_joint_3_actuator">
      <hardwareInterface>EffortJointInterface</hardwareInterface>
      <mechanicalReduction>160</mechanicalReduction>
    </actuator>
  </transmission>
  <link name="m1n6s300_link_4">
    <visual>
      <geometry>
        <mesh filename="meshes/wrist.dae"/>
      </geometry>
      <material name="carbon_fiber">
        <color rgba="0.792156862745098 0.819607843137255 0.933333333333333 1"/>
      </material>
    </visual>
    <visual>
      <geometry>
        <mesh filename="meshes/ring_small.STL"/>
      </geometry>
    </visual>
    <collision>
      <geometry>
        <mesh filename="meshes/wrist.dae"/>
      </geometry>
    </collision>
    <inertial>
      <mass value="0.1785"/>
      <origin xyz="0 -0.037 -0.0642"/>
      <inertia ixx="7.73496906e-05" ixy="0" ixz="0" iyy="7.73496906e-05" iyz="0" izz="0.0001428"/>
    </inertial>
  </link>
  <joint name="m1n6s300_joint_4" type="continuous">
    <parent link="m1n6s300_link_3"/>
    <child link="m1n6s300_link_4"/>
    <axis xyz="0 0 1"/>
    <limit effort="2000" lower="-6.28318530718" upper="6.28318530718" velocity="1"/>
    <origin rpy="-1.57079632679 0 3.14159265359" xyz="0 0.1231 -0.0086"/>
    <dynamics damping="0.0" friction="0.0"/>
  </joint>
  <transmission name="m1n6s300_joint_4_trans">
    <type>transmission_interface/SimpleTransmission</type>
    <joint name="m1n6s300_joint_4">
      <hardwareInterface>EffortJointInterface</hardwareInterface>
    </joint>
    <actuator name="m1n6s300_joint_4_actuator">
      <hardwareInterface>EffortJointInterface</hardwareInterface>
      <mechanicalReduction>160</mechanicalReduction>
    </actuator>
  </transmission>
  <link name="m1n6s300_link_5">
    <visual>
      <geometry>
        <mesh filename="meshes/wrist.dae"/>
      </geometry>
      <material name="carbon_fiber">
        <color rgba="0.792156862745098 0.819607843137255 0.933333333333333 1"/>
      </material>
    </visual>
    <visual>
      <geometry>
        <mesh filename="meshes/ring_small.STL"/>
      </geometry>
    </visual>
    <collision>
      <geometry>
        <mesh filename="meshes/wrist.dae"/>
      </geometry>
    </collision>
    <inertial>
      <mass value="0.1785"/>
      <origin xyz="0 -0.037 -0.0642"/>
      <inertia ixx="7.73496906e-05" ixy="0" ixz="0" iyy="7.73496906e-05" iyz="0" izz="0.0001428"/>
    </inertial>
  </link>
  <joint name="m1n6s300_joint_5" type="continuous">
    <parent link="m1n6s300_link_4"/>
    <child link="m1n6s300_link_5"/>
    <axis xyz="0 0 1"/>
    <limit effort="2000" lower="-6.28318530718" upper="6.28318530718" velocity="1"/>
    <origin rpy="1.0471975512 0 3.14159265359" xyz="0 -0.03703 -0.06414"/>
    <dynamics damping="0.0" friction="0.0"/>
  </joint>
  <transmission name="m1n6s300_joint_5_trans">
    <type>transmission_interface/SimpleTransmission</type>
    <joint name="m1n6s300_joint_5">
      <hardwareInterface>EffortJointInterface</hardwareInterface>
    </joint>
    <actuator name="m1n6s300_joint_5_actuator">
      <hardwareInterface>EffortJointInterface</hardwareInterface>
      <mechanicalReduction>160</mechanicalReduction>
    </actuator>
  </transmission>
  <joint name="m1n6s300_joint_6" type="continuous">
    <parent link="m1n6s300_link_5"/>
    <child link="ft_mount"/>
    <axis xyz="0 0 1"/>
    <limit effort="2000" lower="-6.28318530718" upper="6.28318530718" velocity="1"/>
    <origin rpy="1.0471975512 0 3.14159265359" xyz="0 -0.03703 -0.06414"/>
    <dynamics damping="0.0" friction="0.0"/>
  </joint>
  <transmission name="m1n6s300_joint_6_trans">
    <type>transmission_interface/SimpleTransmission</type>
    <joint name="m1n6s300_joint_6">
      <hardwareInterface>EffortJointInterface</hardwareInterface>
    </joint>
    <actuator name="m1n6s300_joint_6_actuator">
      <hardwareInterface>EffortJointInterface</hardwareInterface>
      <mechanicalReduction>160</mechanicalReduction>
    </actuator>
  </transmission>
  <link name="ft_mount">
    <visual>
      <geometry>
        <mesh filename="meshes/force_torque_mount.stl"/>
      </geometry>
      <material name="carbon_fiber">
        <color rgba="0.792156862745098 0.819607843137255 0.933333333333333 1"/>
      </material>
      <origin rpy="3.14159265359 0 3.14159265359" xyz="0 0 0"/>
    </visual>
    <inertial>
      <mass value="0.0431"/>
      <inertia ixx="0.001" ixy="0.0" ixz="0.0" iyy="0.001" iyz="0.0" izz="0.001"/>
    </inertial>
  </link>
  <!--         <joint name="ft_mount_joint_7" type="fixed" >
            <parent link="${prefix}_link_6" />
            <child link="ft_mount" />
        </joint> -->
  <!-- mount the fts to the robot -->
  <joint name="ft_mount_fts_fix" type="fixed">
    <!--In most cases origin would be flange adapter plate: <origin xyz="0 0 0.009" rpy="0 0 0"/> /-->
    <origin rpy="0 3.14159265359 -1.57079632679" xyz="0 0 -0.03513"/>
    <parent link="ft_mount"/>
    <child link="ft_mount_fts_robotside"/>
  </joint>
  <link name="ft_mount_fts_robotside">
    <inertial>
      <origin rpy="0 0 0" xyz="0 0 0.01875"/>
      <mass value="0.65"/>
      <inertia ixx="0.000661171875" ixy="0" ixz="0" iyy="0.000661171875" iyz="0" izz="0.00117"/>
    </inertial>
    <visual>
      <origin rpy="0 0 0" xyz="0 0 0"/>
      <geometry>
        <mesh filename="meshes/robotiq_ft_sensor.stl"/>
      </geometry>
      <material name="carbon_fiber">
        <color rgba="0.792156862745098 0.819607843137255 0.933333333333333 1"/>
      </material>
    </visual>
    <collision>
      <origin rpy="0 0 0" xyz="0 0 0"/>
      <geometry>
        <mesh filename="meshes/robotiq_ft_sensor.stl"/>
      </geometry>
    </collision>
  </link>
  <!-- virtual measurement frame -->
  <joint name="ft_mount_measurment_joint" type="fixed">
    <origin rpy="0 -1.57079632679 0" xyz="0 0 0.0348"/>
    <parent link="ft_mount_fts_robotside"/>
    <child link="ft_mount_robotiq_ft_frame_id"/>
  </joint>
  <link name="ft_mount_robotiq_ft_frame_id"/>
  <!-- toolside frame -->
  <joint name="ft_mount_toolside_joint" type="fixed">
    <origin rpy="0 -1.57079632679 0" xyz="0 0 0.0348"/>
    <parent link="ft_mount_fts_robotside"/>
    <child link="ft_mount_fts_toolside"/>
  </joint>
  <link name="ft_mount_fts_toolside"/>
  <link name="gripper_mount">
    <visual>
      <geometry>
        <mesh filename="meshes/gripper_mount.stl"/>
      </geometry>
      <material name="carbon_fiber">
        <color rgba="0.792156862745098 0.819607843137255 0.933333333333333 1"/>
      </material>
      <origin rpy="1.57079632679 1.57079632679 0" xyz="-0.0065 0 0"/>
    </visual>
    <inertial>
      <mass value="0.04"/>
      <inertia ixx="0.001" ixy="0.0" ixz="0.0" iyy="0.001" iyz="0.0" izz="0.001"/>
    </inertial>
  </link>
  <joint name="gripper_mount_joint_7" type="fixed">
    <parent link="ft_mount_fts_toolside"/>
    <child link="gripper_mount"/>
  </joint>
  <link name="gripper_link"/>
  <joint name="gripper_rectify" type="fixed">
    <origin rpy="1.57079632679 3.14159265359 -1.57079632679" xyz="0.008 0 0"/>
    <parent link="gripper_mount"/>
    <child link="gripper_link"/>
  </joint>
  <link name="m1n6s300_link_6">
    <visual>
      <geometry>
        <mesh filename="meshes/hand_3finger.dae"/>
      </geometry>
      <material name="carbon_fiber">
        <color rgba="0.792156862745098 0.819607843137255 0.933333333333333 1"/>
      </material>
    </visual>
    <collision>
      <geometry>
        <mesh filename="meshes/hand_3finger.dae"/>
      </geometry>
    </collision>
    <inertial>
      <mass value="0.727"/>
      <origin xyz="0 0 -0.06"/>
      <inertia ixx="0.0003453236187" ixy="0" ixz="0" iyy="0.0003453236187" iyz="0" izz="0.0005816"/>
    </inertial>
  </link>
  <joint name="gripper_mount_link_8" type="fixed">
    <parent link="gripper_link"/>
    <child link="m1n6s300_link_6"/>
  </joint>
  <link name="m1n6s300_end_effector">
    <!--visual>
                <geometry>
                    <box size = "0.01 0.01 0.01"/>
                </geometry>
            </visual>
            <collision>
                <geometry>
                    <box size = "0.01 0.01 0.01"/>
                </geometry>
            </collision-->
  </link>
  <joint name="m1n6s300_joint_end_effector" type="fixed">
    <parent link="m1n6s300_link_6"/>
    <child link="m1n6s300_end_effector"/>
    <axis xyz="0 0 0"/>
    <limit effort="2000" lower="0" upper="0" velocity="1"/>
    <origin rpy="3.14159265359 0 0" xyz="0 0 -0.1600"/>
  </joint>
 <link name="m1n6s300_link_finger_1">
    <visual>
      <geometry>
        <mesh filename="meshes/finger_proximal.dae"/>
      </geometry>
      <material name="carbon_fiber">
        <color rgba="0.792156862745098 0.819607843137255 0.933333333333333 1"/>
      </material>
    </visual>
    <collision>
      <geometry>
        <mesh filename="meshes/finger_proximal.dae"/>
      </geometry>
    </collision>
    <inertial>
      <mass value="0.01"/>
      <origin xyz="0.022 0 0"/>
      <inertia ixx="7.8999684e-07" ixy="0" ixz="0" iyy="7.8999684e-07" iyz="0" izz="8e-08"/>
    </inertial>
  </link>
  <joint name="m1n6s300_joint_finger_1" type="revolute">
    <parent link="m1n6s300_link_6"/>
    <child link="m1n6s300_link_finger_1"/>
    <axis xyz="0 0 1"/>
    <origin rpy="-1.570796327 0.93200578166 1.35961148639407" xyz="0.00279 0.03126 -0.11467"/>
    <limit effort="2" lower="0" upper="1.51" velocity="1"/>
  </joint>
  <transmission name="m1n6s300_joint_finger_1_trans">
    <type>transmission_interface/SimpleTransmission</type>
    <joint name="m1n6s300_joint_finger_1">
      <hardwareInterface>hardware_interface/EffortJointInterface</hardwareInterface>
    </joint>
    <actuator name="m1n6s300_joint_finger_1_actuator">
      <hardwareInterface>hardware_interface/EffortJointInterface</hardwareInterface>
      <mechanicalReduction>1</mechanicalReduction>
    </actuator>
  </transmission>
  <link name="m1n6s300_link_finger_tip_1">
    <visual>
      <geometry>
        <mesh filename="meshes/finger_distal.dae"/>
      </geometry>
      <material name="carbon_fiber">
        <color rgba="0.792156862745098 0.819607843137255 0.933333333333333 1"/>
      </material>
    </visual>
    <collision>
      <geometry>
        <mesh filename="meshes/finger_distal.dae"/>
      </geometry>
    </collision>
    <inertial>
      <mass value="0.01"/>
      <origin xyz="0.022 0 0"/>
      <inertia ixx="7.8999684e-07" ixy="0" ixz="0" iyy="7.8999684e-07" iyz="0" izz="8e-08"/>
    </inertial>
  </link>
  <joint name="m1n6s300_joint_finger_tip_1" type="revolute">
    <parent link="m1n6s300_link_finger_1"/>
    <child link="m1n6s300_link_finger_tip_1"/>
    <axis xyz="0 0 1"/>
    <origin rpy="0 0 0" xyz="0.044 -0.003 0"/>
    <limit effort="2" lower="0" upper="2" velocity="1"/>
  </joint>
  <transmission name="m1n6s300_joint_finger_tip_1_trans">
    <type>transmission_interface/SimpleTransmission</type>
    <joint name="m1n6s300_joint_finger_tip_1">
      <hardwareInterface>hardware_interface/EffortJointInterface</hardwareInterface>
    </joint>
    <actuator name="m1n6s300_joint_finger_tip_1_actuator">
      <hardwareInterface>hardware_interface/EffortJointInterface</hardwareInterface>
      <mechanicalReduction>1</mechanicalReduction>
    </actuator>
  </transmission>
  <link name="m1n6s300_link_finger_2">
    <visual>
      <geometry>
        <mesh filename="meshes/finger_proximal.dae"/>
      </geometry>
      <material name="carbon_fiber">
        <color rgba="0.792156862745098 0.819607843137255 0.933333333333333 1"/>
      </material>
    </visual>
    <collision>
      <geometry>
        <mesh filename="meshes/finger_proximal.dae"/>
      </geometry>
    </collision>
    <inertial>
      <mass value="0.01"/>
      <origin xyz="0.022 0 0"/>
      <inertia ixx="7.8999684e-07" ixy="0" ixz="0" iyy="7.8999684e-07" iyz="0" izz="8e-08"/>
    </inertial>
  </link>
  <joint name="m1n6s300_joint_finger_2" type="revolute">
    <parent link="m1n6s300_link_6"/>
    <child link="m1n6s300_link_finger_2"/>
    <axis xyz="0 0 1"/>
    <origin rpy="-1.570796327 0.93200578166 -1.38614049188413" xyz="0.02226 -0.02707 -0.11482"/>
    <limit effort="2" lower="0" upper="1.51" velocity="1"/>
  </joint>
  <transmission name="m1n6s300_joint_finger_2_trans">
    <type>transmission_interface/SimpleTransmission</type>
    <joint name="m1n6s300_joint_finger_2">
      <hardwareInterface>hardware_interface/EffortJointInterface</hardwareInterface>
    </joint>
    <actuator name="m1n6s300_joint_finger_2_actuator">
      <hardwareInterface>hardware_interface/EffortJointInterface</hardwareInterface>
      <mechanicalReduction>1</mechanicalReduction>
    </actuator>
  </transmission>
  <link name="m1n6s300_link_finger_tip_2">
    <visual>
      <geometry>
        <mesh filename="meshes/finger_distal.dae"/>
      </geometry>
      <material name="carbon_fiber">
        <color rgba="0.792156862745098 0.819607843137255 0.933333333333333 1"/>
      </material>
    </visual>
    <collision>
      <geometry>
        <mesh filename="meshes/finger_distal.dae"/>
      </geometry>
    </collision>
    <inertial>
      <mass value="0.01"/>
      <origin xyz="0.022 0 0"/>
      <inertia ixx="7.8999684e-07" ixy="0" ixz="0" iyy="7.8999684e-07" iyz="0" izz="8e-08"/>
    </inertial>
  </link>
  <joint name="m1n6s300_joint_finger_tip_2" type="revolute">
    <parent link="m1n6s300_link_finger_2"/>
    <child link="m1n6s300_link_finger_tip_2"/>
    <axis xyz="0 0 1"/>
    <origin rpy="0 0 0" xyz="0.044 -0.003 0"/>
    <limit effort="2" lower="0" upper="2" velocity="1"/>
  </joint>
  <transmission name="m1n6s300_joint_finger_tip_2_trans">
    <type>transmission_interface/SimpleTransmission</type>
    <joint name="m1n6s300_joint_finger_tip_2">
      <hardwareInterface>hardware_interface/EffortJointInterface</hardwareInterface>
    </joint>
    <actuator name="m1n6s300_joint_finger_tip_2_actuator">
      <hardwareInterface>hardware_interface/EffortJointInterface</hardwareInterface>
      <mechanicalReduction>1</mechanicalReduction>
    </actuator>
  </transmission>
  <link name="m1n6s300_link_finger_3">
    <visual>
      <geometry>
        <mesh filename="meshes/finger_proximal.dae"/>
      </geometry>
      <material name="carbon_fiber">
        <color rgba="0.792156862745098 0.819607843137255 0.933333333333333 1"/>
      </material>
    </visual>
    <collision>
      <geometry>
        <mesh filename="meshes/finger_proximal.dae"/>
      </geometry>
    </collision>
    <inertial>
      <mass value="0.01"/>
      <origin xyz="0.022 0 0"/>
      <inertia ixx="7.8999684e-07" ixy="0" ixz="0" iyy="7.8999684e-07" iyz="0" izz="8e-08"/>
    </inertial>
  </link>
  <joint name="m1n6s300_joint_finger_3" type="revolute">
    <parent link="m1n6s300_link_6"/>
    <child link="m1n6s300_link_finger_3"/>
    <axis xyz="0 0 1"/>
    <origin rpy="-1.570796327 0.93200578166 -1.75545216211587" xyz="-0.02226 -0.02707 -0.11482"/>
    <limit effort="2" lower="0" upper="1.51" velocity="1"/>
  </joint>
  <transmission name="m1n6s300_joint_finger_3_trans">
    <type>transmission_interface/SimpleTransmission</type>
    <joint name="m1n6s300_joint_finger_3">
      <hardwareInterface>hardware_interface/EffortJointInterface</hardwareInterface>
    </joint>
    <actuator name="m1n6s300_joint_finger_3_actuator">
      <hardwareInterface>hardware_interface/EffortJointInterface</hardwareInterface>
      <mechanicalReduction>1</mechanicalReduction>
    </actuator>
  </transmission>
  <link name="m1n6s300_link_finger_tip_3">
    <visual>
      <geometry>
        <mesh filename="meshes/finger_distal.dae"/>
      </geometry>
      <material name="carbon_fiber">
        <color rgba="0.792156862745098 0.819607843137255 0.933333333333333 1"/>
      </material>
    </visual>
    <collision>
      <geometry>
        <mesh filename="meshes/finger_distal.dae"/>
      </geometry>
    </collision>
    <inertial>
      <mass value="0.01"/>
      <origin xyz="0.022 0 0"/>
      <inertia ixx="7.8999684e-07" ixy="0" ixz="0" iyy="7.8999684e-07" iyz="0" izz="8e-08"/>
    </inertial>
  </link>
  <joint name="m1n6s300_joint_finger_tip_3" type="revolute">
    <parent link="m1n6s300_link_finger_3"/>
    <child link="m1n6s300_link_finger_tip_3"/>
    <axis xyz="0 0 1"/>
    <origin rpy="0 0 0" xyz="0.044 -0.003 0"/>
    <limit effort="2" lower="0" upper="2" velocity="1"/>
  </joint>
  <transmission name="m1n6s300_joint_finger_tip_3_trans">
    <type>transmission_interface/SimpleTransmission</type>
    <joint name="m1n6s300_joint_finger_tip_3">
      <hardwareInterface>hardware_interface/EffortJointInterface</hardwareInterface>
    </joint>
    <actuator name="m1n6s300_joint_finger_tip_3_actuator">
      <hardwareInterface>hardware_interface/EffortJointInterface</hardwareInterface>
      <mechanicalReduction>1</mechanicalReduction>
    </actuator>
  </transmission>
</robot>
