
<?xml version="1.0" ?>

<robot name="kawasaki">
    
    <!-- Import Rviz colors -->
    <material name="Grey">
        <color rgba="0.2 0.2 0.2 1.0"/>
    </material>
    <material name="Orange">
        <color rgba="1.0 0.423529411765 0.0392156862745 1.0"/>
    </material>
    <material name="Blue">
        <color rgba="0.5 0.7 1.0 1.0"/>      
    </material>
    
    
    <link name="base">
        <inertial>
            <mass value="1000000"/>
            <inertia ixx="100"  ixy="0"  ixz="0" iyy="100" iyz="0" izz="100" />
	    </inertial>
        <visual>
            <origin xyz="0 0 0" rpy="0.0 0.0 0.0"/>
            <geometry>
                <mesh filename="meshes/base.dae"/>
            </geometry>
            <material name="Grey"/>
        </visual>
        
        <collision>
            <geometry>
                <mesh filename="meshes/base.dae"/>
            </geometry>
        </collision>
        
    </link>  
    
    
    <link name="link_1">
        <inertial>
            <mass value="10"/>
            <inertia ixx="100"  ixy="0"  ixz="0" iyy="100" iyz="0" izz="100" />
	    </inertial>
        <visual>
            <origin xyz="0 0 0" rpy="0.0 0.0 0.0"/>
            <geometry>
                <mesh filename="meshes/link_1.dae"/>
            </geometry>
            <material name="Blue"/>
        </visual>
        
    </link>  
    
    
    <link name="link_2">
        <inertial>
            <mass value="10"/>
            <inertia ixx="100"  ixy="0"  ixz="0" iyy="100" iyz="0" izz="100" />
	    </inertial>
        <visual>
            <origin xyz="0 -0.2 -0.53" rpy="0.0 0.0 0.0"/>
            <geometry>
                <mesh filename="meshes/link_2.dae"/>
            </geometry>
            <material name="Orange"/>
        </visual>
        
    </link>  
    
    
    <link name="link_3">
        <inertial>
            <mass value="10"/>
            <inertia ixx="100"  ixy="0"  ixz="0" iyy="100" iyz="0" izz="100" />
	    </inertial>
        <visual>
            <origin xyz="0 -0.2 -1.69" rpy="0 0 0"/>
            <geometry>
                <mesh filename="meshes/link_3.dae"/>
            </geometry>
            <material name="Grey"/>
        </visual>
        
    </link>  
    
    
    <link name="link_4">
        <inertial>
            <mass value="10"/>
            <inertia ixx="100"  ixy="0"  ixz="0" iyy="100" iyz="0" izz="100" />
	    </inertial>
        <visual>
            <origin xyz="0 -1.45 -1.92" rpy="0 0 0"/>
            <geometry>
                <mesh filename="meshes/link_4.dae"/>
            </geometry>
            <material name="Blue"/>
        </visual>
        
    </link>  
    
    
    <link name="link_5">
        <inertial>
            <mass value="10"/>
            <inertia ixx="100"  ixy="0"  ixz="0" iyy="100" iyz="0" izz="100" />
	    </inertial>
        <visual>
            <origin xyz="0 -1.45 -1.92" rpy="0 0 0"/>
            <geometry>
                <mesh filename="meshes/link_5.dae"/>
            </geometry>
            <material name="Orange"/>
        </visual>
        
    </link>  
    
    
    <link name="link_6">
        <inertial>
            <mass value="10"/>
            <inertia ixx="100"  ixy="0"  ixz="0" iyy="100" iyz="0" izz="100" />
	    </inertial>
        <visual>
            <origin xyz="0 -1.675 -1.92" rpy="0 0 0"/>
            <geometry>
                <mesh filename="meshes/link_6.dae"/>
            </geometry>
            <material name="Grey"/>
        </visual>
        
    </link>  
    
      

    
    <joint name="joint_1" type="revolute">
        <parent link="base"/>
        <child link="link_1"/>
        <origin xyz="0 0 0" rpy="0.0 0.0 0.0"/>
        <axis xyz="0 0 1"/>
        <limit effort="300" lower="-2.96705972839" upper="2.96705972839" velocity="10"/>
        <dynamics damping="0.5"/>
    </joint> 
	
    <joint name="joint_2" type="revolute">
        <parent link="link_1"/>
        <child link="link_2"/>
        <origin xyz="0 0.2 0.53" rpy="0.0 0.0 0.0"/>
        <axis xyz="1 0 0"/>
        <limit effort="300" lower="-2.96705972839" upper="2.96705972839" velocity="10"/>
        <dynamics damping="0.5"/>
    </joint> 
	
    <joint name="joint_3" type="revolute">
        <parent link="link_2"/>
        <child link="link_3"/>
        <origin xyz="0 0 1.16" rpy="0.0 0.0 0.0"/>
        <axis xyz="1 0 0"/>
        <limit effort="300" lower="-2.96705972839" upper="2.96705972839" velocity="10"/>
        <dynamics damping="0.5"/>
    </joint> 
	
    <joint name="joint_4" type="revolute">
        <parent link="link_3"/>
        <child link="link_4"/>
        <origin xyz="0 1.25 0.23" rpy="0.0 0.0 0.0"/>
        <axis xyz="0 1 0"/>
        <limit effort="300" lower="-2.96705972839" upper="2.96705972839" velocity="10"/>
        <dynamics damping="0.5"/>
    </joint> 
	
    <joint name="joint_5" type="revolute">
        <parent link="link_4"/>
        <child link="link_5"/>
        <origin xyz="0 0 0" rpy="0.0 0.0 0.0"/>
        <axis xyz="1 0 0"/>
        <limit effort="300" lower="-2.96705972839" upper="2.96705972839" velocity="10"/>
        <dynamics damping="0.5"/>
    </joint> 
	
    <joint name="joint_6" type="revolute">
        <parent link="link_5"/>
        <child link="link_6"/>
        <origin xyz="0 0.225 0" rpy="0.0 0.0 0.0"/>
        <axis xyz="0 1 0"/>
        <limit effort="300" lower="-2.96705972839" upper="2.96705972839" velocity="10"/>
        <dynamics damping="0.5"/>
    </joint> 
	
	
</robot>