<?xml version="1.0" ?>

<robot name="kawasaki" xmlns:xacro="http://www.ros.org/wiki/xacro">
  <!-- Import Rviz colors -->
  <material name="Grey">
	<color rgba="0.2 0.2 0.2 1.0"/>
  </material>
  <material name="Orange">
	<color rgba="1.0 0.423529411765 0.0392156862745 1.0"/>
  </material>
  <material name="Blue">
  <color rgba="0.5 0.7 1.0 1.0"/>      
</material>

  <!--Import the lbr iiwa macro -->
  <!--Import Transmissions -->
  <!--Include Utilities -->
  <!--The following macros are adapted from the LWR 4 definitions of the RCPRG - https://github.com/RCPRG-ros-pkg/lwr_robot -->
  <!--Little helper macros to define the inertia matrix needed for links.-->
  <!--Cuboid-->
  <!--Cylinder: length is along the y-axis! -->
  <!--lbr-->
  <link name="base">
	<origin rpy="0 0 0" xyz="2 0 0"/>
	<inertial>
		<origin xyz="0 0 0" rpy="0 0 0"/>
		<mass value="100"/>
		<inertia ixx="1000"  ixy="0"  ixz="0" iyy="1000" iyz="0" izz="1000" />
	</inertial>
	<visual>
	  <origin rpy="0 0 0" xyz="0 0 0"/>
	  <geometry>
		<mesh filename="meshes/base.dae"/>
	  </geometry>
	  <material name="Grey"/>
	</visual>
	<collision>
	  <geometry>
		<mesh filename="meshes/base.dae"/>
	  </geometry>
	</collision>
  </link>
  <!-- joint between base and link_1 -->
  <joint name="joint_1" type="revolute">
	<parent link="base"/>
	<child link="link_1"/>
	<origin rpy="0 0 0" xyz="0 0 0.1575"/>
	<axis xyz="0 0 1"/>
	<limit effort="300" lower="-2.96705972839" upper="2.96705972839" velocity="10"/>
	<dynamics damping="0.5"/>
  </joint>
  <link name="link_1">
	<visual>
	  <origin rpy="0 0 0" xyz="0 0 0"/>
	  <geometry>
		<mesh filename="meshes/link_1.dae"/>
	  </geometry>
	  <material name="Blue"/>
	</visual>
	<collision>
	  <origin rpy="0 0 0" xyz="0 0 0"/>
	  <geometry>
		<mesh filename="meshes/link_1.dae"/>
	  </geometry>
	</collision>
  </link>
  <!-- joint between link_1 and link_2 -->
  <joint name="joint_2" type="revolute">
	<parent link="link_1"/>
	<child link="link_2"/>
	<origin rpy="1.57079632679   0 3.14159265359" xyz="0 0 0.2025"/>
	<axis xyz="0 0 1"/>
	<limit effort="300" lower="-2.09439510239" upper="2.09439510239" velocity="10"/>
	<dynamics damping="0.5"/>
  </joint>
  <link name="link_2">
	<visual>
	  <origin rpy="0 0 0" xyz="0 0 0"/>
	  <geometry>
		<mesh filename="meshes/link_2.dae"/>
	  </geometry>
	  <material name="Blue"/>
	</visual>
	<collision>
	  <origin rpy="0 0 0" xyz="0 0 0"/>
	  <geometry>
		<mesh filename="meshes/link_2.dae"/>
	  </geometry>
	</collision>
  </link>
  <!-- joint between link_2 and link_3 -->
  <joint name="joint_3" type="revolute">
	<parent link="link_2"/>
	<child link="link_3"/>
	<origin rpy="1.57079632679 0 3.14159265359" xyz="0 0.2045 0"/>
	<axis xyz="0 0 1"/>
	<limit effort="300" lower="-2.96705972839" upper="2.96705972839" velocity="10"/>
	<dynamics damping="0.5"/>
  </joint>
  <link name="link_3">
	<visual>
	  <origin rpy="0 0 0" xyz="0 0 0"/>
	  <geometry>
		<mesh filename="meshes/link_3.dae"/>
	  </geometry>
	  <material name="Orange"/>
	</visual>
	<collision>
	  <origin rpy="0 0 0" xyz="0 0 0"/>
	  <geometry>
		<mesh filename="meshes/link_3.dae"/>
	  </geometry>
	</collision>
  </link>
  <!-- joint between link_3 and link_4 -->
  <joint name="joint_4" type="revolute">
	<parent link="link_3"/>
	<child link="link_4"/>
	<origin rpy="1.57079632679 0 0" xyz="0 0 0.2155"/>
	<axis xyz="0 0 1"/>
	<limit effort="300" lower="-2.09439510239" upper="2.09439510239" velocity="10"/>
	<dynamics damping="0.5"/>
  </joint>
  <link name="link_4">
	<visual>
	  <origin rpy="0 0 0" xyz="0 0 0"/>
	  <geometry>
		<mesh filename="meshes/link_4.dae"/>
	  </geometry>
	  <material name="Blue"/>
	</visual>
	<collision>
	  <origin rpy="0 0 0" xyz="0 0 0"/>
	  <geometry>
		<mesh filename="meshes/link_4.dae"/>
	  </geometry>
	</collision>
  </link>
  <!-- joint between link_4 and link_5 -->
  <joint name="joint_5" type="revolute">
	<parent link="link_4"/>
	<child link="link_5"/>
	<origin rpy="-1.57079632679 3.14159265359 0" xyz="0 0.1845 0"/>
	<axis xyz="0 0 1"/>
	<limit effort="300" lower="-2.96705972839" upper="2.96705972839" velocity="10"/>
	<dynamics damping="0.5"/>
  </joint>
  <link name="link_5">
	<visual>
	  <origin rpy="0 0 0" xyz="0 0 0"/>
	  <geometry>
		<mesh filename="meshes/link_5.dae"/>
	  </geometry>
	  <material name="Blue"/>
	</visual>
	<collision>
	  <origin rpy="0 0 0" xyz="0 0 0"/>
	  <geometry>
		<mesh filename="meshes/link_5.dae"/>
	  </geometry>
	</collision>
  </link>
  <!-- joint between link_5 and link_6 -->
  <joint name="joint_6" type="revolute">
	<parent link="link_5"/>
	<child link="link_6"/>
	<origin rpy="1.57079632679 0 0" xyz="0 0 0.2155"/>
	<axis xyz="0 0 1"/>
	<limit effort="300" lower="-2.09439510239" upper="2.09439510239" velocity="10"/>
	<dynamics damping="0.5"/>
  </joint>
  <link name="link_6">
	<visual>
	  <origin rpy="0 0 0" xyz="0 0 0"/>
	  <geometry>
		<mesh filename="meshes/link_6.dae"/>
	  </geometry>
	  <material name="Orange"/>
	</visual>
	<collision>
	  <origin rpy="0 0 0" xyz="0 0 0"/>
	  <geometry>
		<mesh filename="meshes/link_6.dae"/>
	  </geometry>
	</collision>
  </link>
	
</robot>

